<?xml version="1.0" ?>
<robot name="cctv">

  <material name="black">
    <color rgba="0.0 0.0 0.0 1.0"/>
  </material>
  <material name="orange">
    <color rgba="1.0 0.4 0.0 1.0"/>
  </material>

  <link name="base"/>

  <joint name="fixed" type="fixed">
    <parent link="base"/>
    <child link="link1"/>
  </joint>

  <link name="link1">
    <collision>
      <origin xyz="0 0 0.006" rpy="0 0 0"/>
      <geometry>
        <box size="0.025 0.25 0.012"/>
      </geometry>
    </collision>
    <visual>
      <origin xyz="0 0 0.006" rpy="0 0 0"/>
      <geometry>
        <box size="0.03 0.025 0.012"/>
      </geometry>
      <material name="black"/>
    </visual>
    <inertial>
      <origin xyz="0 0 0.006" rpy="0 0 0"/>
      <mass value="1"/>
      <inertia ixx="1.0" ixy="0.0" ixz="0.0" iyy="1.0" iyz="0.0" izz="1.0"/>
    </inertial>
  </link>

  <joint name="joint1" type="revolute">
    <parent link="link1"/>
    <child link="link2"/>
    <origin xyz="0 0 0.012" rpy="0 0 0"/>
    <axis xyz="0 0 1"/>
    <limit effort="30" lower="-1.5" upper="1.5" velocity="1.571"/>
  </joint>

  <link name="link2">
    <collision>
      <origin xyz="0 0 0.012" rpy="0 0 0"/>
      <geometry>
        <box size="0.025 0.025 0.03"/>
      </geometry>
    </collision>
    <visual>
      <origin xyz="0 0 0.012" rpy="0 0 0"/>
      <geometry>
        <box size="0.025 0.025 0.03"/>
      </geometry>
      <material name="orange"/>
    </visual>
    <inertial>
      <origin xyz="0 0 0.012" rpy="0 0 0"/>
      <mass value="1"/>
      <inertia ixx="1.0" ixy="0.0" ixz="0.0" iyy="1.0" iyz="0.0" izz="1.0"/>
    </inertial>
  </link>

  <joint name="joint2" type="revolute">
    <parent link="link2"/>
    <child link="link3"/>
    <origin xyz="-0.02 0 0.02" rpy="0 0 0"/>
    <axis xyz="0 1 0"/>
    <limit effort="30" lower="-0.45" upper="1.5" velocity="1.571"/>
  </joint>

  <link name="link3">
    <collision>
      <origin xyz="0 0 0.02" rpy="0 0 0"/>
      <geometry>
        <box size="0.01 0.04 0.04"/>
      </geometry>
    </collision>
    <visual>
      <origin xyz="0 0 0.02" rpy="0 0 0"/>
      <geometry>
        <box size="0.01 0.04 0.04"/>
      </geometry>
      <material name="black"/>
    </visual>
    <inertial>
      <origin xyz="0 0 0.02" rpy="0 0 0"/>
      <mass value="1"/>
      <inertia ixx="1.0" ixy="0.0" ixz="0.0" iyy="1.0" iyz="0.0" izz="1.0"/>
    </inertial>
  </link>

</robot>
